#VRML_SIM R2020b utf8
WorldInfo {
  coordinateSystem "NUE"
}
Viewpoint {
  orientation -0.010272065402168637 0.978977798025452 0.2037080156636226 2.937224707851601
  position 0.1934903532966435 0.5691138201498999 -1.237744607582814
}
TexturedBackground {
}
TexturedBackgroundLight {
}
RectangleArena {
  translation 0 0.01 0
  floorSize 20 20
  floorTileSize 20 20
}
Robot {
  translation -2.34144e-12 0.189296 1.64877e-08
  rotation 0.9999999977138501 6.761877971786651e-05 -2.791184368359738e-08 1.569651221124495e-08
  children [
    Solid {
      children [
        Gyro {
        }
        HingeJoint {
          jointParameters HingeJointParameters {
            position 3.3328985993161354e-11
            axis 0 0 1
            anchor 0.167 0 -0.232
          }
          device [
            PositionSensor {
              name "Front Left Encoder"
            }
            RotationalMotor {
              name "PWM_0"
              maxVelocity 87.4102
            }
          ]
          endPoint Solid {
            translation 0.167 0 -0.232
            rotation 1 2.4995715076178723e-10 2.4995623261959166e-10 1.5708
            children [
              Shape {
                appearance PBRAppearance {
                  metalness 0.5
                }
                geometry DEF Wheel Cylinder {
                  height 0.0125
                  radius 0.0635
                }
              }
            ]
            name "FL"
            boundingObject USE Wheel
            physics Physics {
            }
          }
        }
        HingeJoint {
          jointParameters HingeJointParameters {
            position 3.332184113131792e-11
            axis 0 0 1
            anchor 0 0 -0.232
          }
          device [
            RotationalMotor {
              name "PWM_2"
              maxVelocity 87.4102
            }
          ]
          endPoint Solid {
            translation 0 0 -0.232
            rotation 1 2.665645634896646e-10 2.6656358434514815e-10 1.5708
            children [
              Shape {
                appearance PBRAppearance {
                  metalness 0.5
                }
                geometry USE Wheel
              }
            ]
            name "ML"
            boundingObject USE Wheel
            physics Physics {
            }
          }
        }
        HingeJoint {
          jointParameters HingeJointParameters {
            position 3.332184113131792e-11
            axis 0 0 1
            anchor -0.167 0 -0.232
          }
          device [
            PositionSensor {
              name "Back Left Encoder"
            }
            RotationalMotor {
              name "PWM_4"
              maxVelocity 87.4102
            }
          ]
          endPoint Solid {
            translation -0.167 0 -0.232
            rotation 1 2.3324272235834666e-10 2.3324186561156223e-10 1.5708
            children [
              Shape {
                appearance PBRAppearance {
                  metalness 0.5
                }
                geometry USE Wheel
              }
            ]
            name "BL"
            boundingObject USE Wheel
            physics Physics {
            }
          }
        }
        HingeJoint {
          jointParameters HingeJointParameters {
            position -1.9640895964673523e-14
            axis 0 0 1
            anchor 0.167 0 0.232
          }
          device [
            PositionSensor {
              name "Front Right Encoder"
            }
            RotationalMotor {
              name "PWM_1"
              maxVelocity 87.4102
            }
          ]
          endPoint Solid {
            translation 0.167 0 0.232
            rotation 1 1.66348979090243e-11 1.6634836805744632e-11 1.5708
            children [
              Shape {
                appearance PBRAppearance {
                  metalness 0.5
                }
                geometry USE Wheel
              }
            ]
            name "FR"
            boundingObject USE Wheel
            physics Physics {
            }
          }
        }
        HingeJoint {
          jointParameters HingeJointParameters {
            position 3.332184113131792e-11
            axis 0 0 1
            anchor 0 0 0.232
          }
          device [
            RotationalMotor {
              name "PWM_3"
              maxVelocity 87.4102
            }
          ]
          endPoint Solid {
            translation 0 0 0.232
            rotation 1 2.9988640462098253e-10 2.9988530307873407e-10 1.5708
            children [
              Shape {
                appearance PBRAppearance {
                  metalness 0.5
                }
                geometry USE Wheel
              }
            ]
            name "MR"
            boundingObject USE Wheel
            physics Physics {
            }
          }
        }
        HingeJoint {
          jointParameters HingeJointParameters {
            position -1.9880764725810936e-14
            axis 0 0 1
            anchor -0.167 0 0.232
          }
          device [
            PositionSensor {
              name "Back Right Encoder"
            }
            RotationalMotor {
              name "PWM_5"
              maxVelocity 87.4102
            }
          ]
          endPoint Solid {
            translation -0.167 0 0.232
            rotation 1 1.6636062279477512e-11 1.6636001171920884e-11 1.5708
            children [
              Shape {
                appearance PBRAppearance {
                  metalness 0.5
                }
                geometry USE Wheel
              }
            ]
            name "BR"
            boundingObject USE Wheel
            physics Physics {
            }
          }
        }
        Shape {
          appearance PBRAppearance {
          }
          geometry DEF Base Box {
            size 0.46101 0.05 0.45085
          }
        }
      ]
      boundingObject USE Base
      physics Physics {
      }
    }
    Pen {
      translation 0 0.001 0
      inkColor 1 0 0
      inkDensity 1
      leadSize 0.1
    }
  ]
  boundingObject USE Base
  physics Physics {
    density -1
    mass 10
  }
  controller "<extern>"
}
