#VRML_SIM R2020b utf8
WorldInfo {
  coordinateSystem "NUE"
}
Viewpoint {
  orientation -0.010272065402168637 0.978977798025452 0.2037080156636226 2.937224707851601
  position 0.1934903532966435 0.5691138201498999 -1.237744607582814
}
TexturedBackground {
}
TexturedBackgroundLight {
}
RectangleArena {
  translation 0 0.01 0
  floorSize 20 20
  floorTileSize 20 20
}
Robot {
  translation -2.117237508055587e-12 0.07065492413992273 1.6108886531155762e-08
  rotation 0.9999999973552158 7.267785200919476e-05 -2.7382634108036116e-06 9.671819832281801e-09
  children [
    Solid {
      children [
        Gyro {
        }
        HingeJoint {
          jointParameters HingeJointParameters {
            position 4.360926197640726e-11
            axis 0 0 1
            anchor 0.167 0 -0.232
          }
          device [
            PositionSensor {
              name "Front Left Encoder"
            }
            RotationalMotor {
              name "PWM_0"
              maxVelocity 87.4102
            }
          ]
          endPoint Solid {
            translation 0.167 0 -0.232
            rotation 1 2.884262747465716e-10 2.88425215299653e-10 1.5708
            children [
              Shape {
                appearance PBRAppearance {
                  metalness 0.5
                }
                geometry DEF Wheel Cylinder {
                  height 0.0125
                  radius 0.0635
                }
              }
            ]
            name "FL"
            boundingObject USE Wheel
            physics Physics {
            }
            linearVelocity -6.294306294674108e-12 1.1447743263747634e-06 -1.3434188676116685e-11
            angularVelocity -2.0598918115330398e-10 6.9999456144312314e-12 1.018961886342007e-10
          }
        }
        HingeJoint {
          jointParameters HingeJointParameters {
            position 4.360448175527192e-11
            axis 0 0 1
            anchor 0 0 -0.232
          }
          device [
            RotationalMotor {
              name "PWM_2"
              maxVelocity 87.4102
            }
          ]
          endPoint Solid {
            translation 0 0 -0.232
            rotation 1 3.050277249329596e-10 3.050266045056217e-10 1.5708
            children [
              Shape {
                appearance PBRAppearance {
                  metalness 0.5
                }
                geometry USE Wheel
              }
            ]
            name "ML"
            boundingObject USE Wheel
            physics Physics {
            }
            linearVelocity -6.2951303547069035e-12 1.1447746041071323e-06 -1.3078061638388128e-11
            angularVelocity -2.0591579473840665e-10 6.999945614210316e-12 1.0191248172866399e-10
          }
        }
        HingeJoint {
          jointParameters HingeJointParameters {
            position 4.3601892082558425e-11
            axis 0 0 1
            anchor -0.167 0 -0.232
          }
          device [
            PositionSensor {
              name "Back Left Encoder"
            }
            RotationalMotor {
              name "PWM_4"
              maxVelocity 87.4102
            }
          ]
          endPoint Solid {
            translation -0.167 0 -0.232
            rotation 1 2.7170458896528487e-10 2.717035909404352e-10 1.5708
            children [
              Shape {
                appearance PBRAppearance {
                  metalness 0.5
                }
                geometry USE Wheel
              }
            ]
            name "BL"
            boundingObject USE Wheel
            physics Physics {
            }
            linearVelocity -6.294428607315576e-12 1.1447748753543762e-06 -1.2723839276645889e-11
            angularVelocity -2.0589386402112224e-10 6.999945614335159e-12 1.0189498014443489e-10
          }
        }
        HingeJoint {
          jointParameters HingeJointParameters {
            position 1.0261485809340026e-11
            axis 0 0 1
            anchor 0.167 0 0.232
          }
          device [
            PositionSensor {
              name "Front Right Encoder"
            }
            RotationalMotor {
              name "PWM_1"
              maxVelocity 87.4102
            }
          ]
          endPoint Solid {
            translation 0.167 0 0.232
            rotation 1 2.1765640813694315e-11 2.176556086417824e-11 1.5708
            children [
              Shape {
                appearance PBRAppearance {
                  metalness 0.5
                }
                geometry USE Wheel
              }
            ]
            name "FR"
            boundingObject USE Wheel
            physics Physics {
            }
            linearVelocity -5.306817147298672e-12 1.1448697538770572e-06 -1.3434286886323714e-11
            angularVelocity -2.0599074097035034e-10 6.999946143073629e-12 1.0174850932434077e-10
          }
        }
        HingeJoint {
          jointParameters HingeJointParameters {
            position 4.360166522661329e-11
            axis 0 0 1
            anchor 0 0 0.232
          }
          device [
            RotationalMotor {
              name "PWM_3"
              maxVelocity 87.4102
            }
          ]
          endPoint Solid {
            translation 0 0 0.232
            rotation 1 3.3834815779994814e-10 3.383469149800512e-10 1.5708
            children [
              Shape {
                appearance PBRAppearance {
                  metalness 0.5
                }
                geometry USE Wheel
              }
            ]
            name "MR"
            boundingObject USE Wheel
            physics Physics {
            }
            linearVelocity -5.307116563745509e-12 1.144870032324018e-06 -1.3080180525239821e-11
            angularVelocity -2.059652943082712e-10 6.999946142624644e-12 1.0175384160100531e-10
          }
        }
        HingeJoint {
          jointParameters HingeJointParameters {
            position -1.030143415117446e-11
            axis 0 0 1
            anchor -0.167 0 0.232
          }
          device [
            PositionSensor {
              name "Back Right Encoder"
            }
            RotationalMotor {
              name "PWM_5"
              maxVelocity 87.4102
            }
          ]
          endPoint Solid {
            translation -0.167 0 0.232
            rotation 1 1.1485345203890282e-11 1.1485303015939155e-11 1.5708
            children [
              Shape {
                appearance PBRAppearance {
                  metalness 0.5
                }
                geometry USE Wheel
              }
            ]
            name "BR"
            boundingObject USE Wheel
            physics Physics {
            }
            linearVelocity 3.84838232771976e-12 1.144870295451431e-06 -1.2723212274524775e-11
            angularVelocity -2.0587984352697302e-10 6.99994607305346e-12 -1.048318340105883e-10
          }
        }
        Shape {
          appearance PBRAppearance {
          }
          geometry DEF Base Box {
            size 0.46101 0.05 0.45085
          }
        }
      ]
      boundingObject USE Base
      physics Physics {
      }
    }
    Pen {
      translation 0 0.001 0
      inkColor 1 0 0
      inkDensity 1
      leadSize 0.1
    }
  ]
  boundingObject USE Base
  physics Physics {
    density -1
    mass 10
  }
  controller "WPILibWebSocketsToWebots"
  linearVelocity -4.2648216424411256e-12 1.148528369534468e-06 -1.3061368249292495e-11
  angularVelocity -2.059338555877361e-10 7.000552244348334e-12 -1.6645197715253944e-12
}
